<?xml version="1.0"?>
<robot xmlns:xacro="http://www.ros.org/wiki/xacro">
  <xacro:macro name="diffbot" params="prefix">

    <xacro:property name="PI" value="3.1415926535897931"/>
    <xacro:property name="base_mass" value="0.3" /> 
    <xacro:property name="base_width" value="0.3" />
    <xacro:property name="base_length" value="0.3" />
    <xacro:property name="base_height" value="0.14" />
    <xacro:property name="wheel_mass" value="0.3" /> 
    <xacro:property name="wheel_len" value="0.03175" />
    <xacro:property name="wheel_radius" value="0.04445" />
    <xacro:property name="caster_wheel_mass" value="0.1" /> 
    <xacro:property name="caster_wheel_radius" value="0.03445" />
    <xacro:property name="z_offset" value="0.0" /> 
    <xacro:property name="wheel_distance_from_center" value="0.10" />

    <link name="${prefix}base_link">
      <collision>
        <origin xyz="0 0 0" rpy="0 0 0"/>
        <geometry>
          <box size="${base_width} ${base_length} ${base_height}"/>
        </geometry>
      </collision>
      <visual>
        <origin xyz="0 0 0.06" rpy="0 0 0"/>
        <geometry>
          <box size="${base_width} ${base_length} ${base_height}"/>
        </geometry>
        <material name="orange"/>
      </visual>
      <inertial>
        <origin xyz="0 0 0" rpy="0 0 0"/>
        <mass value="${base_mass}"/>
        <inertia
          ixx="${base_mass / 12.0 * (base_length*base_length + base_height*base_height)}" ixy="0.0" ixz="0.0"
          iyy="${base_mass / 12.0 * (base_height*base_height + base_width*base_width)}" iyz="0.0"
          izz="${base_mass / 12.0 * (base_width*base_width + base_length*base_length)}"/>
      </inertial>
    </link>

   <joint name="${prefix}imu_chassis_joint" type="fixed">
        <parent link="${prefix}base_link"/>
        <child link="${prefix}imu_chassis"/>
        <origin xyz="-0.15 0.0 0.0" rpy="0 0 0"/>
    </joint>
    <link name="${prefix}imu_chassis"></link>

    <joint name="${prefix}mag_chassis_joint" type="fixed">
        <parent link="${prefix}imu_chassis"/>
        <child link="${prefix}mag_chassis"/>
        <origin xyz="0.0 0.0 0.0" rpy="${pi} 0 ${pi/2}"/>
    </joint>
    <link name="${prefix}mag_chassis"></link>

    <joint name="${prefix}base_footprint_joint" type="fixed">
      <parent link="${prefix}base_link"/>
      <child link="${prefix}base_footprint"/>
      <origin xyz="0 0 0" rpy="0 0 0"/>
    </joint>
    <link name="${prefix}base_footprint">
    </link>

    <joint name="${prefix}left_wheel_joint" type="continuous">
      <parent link="${prefix}base_link"/>
      <child link="${prefix}left_wheel"/>
      <origin xyz="${wheel_distance_from_center} ${base_width/2} ${z_offset}" rpy="0 0 0"/>
      <axis xyz="0 1 0"/>
      <dynamics damping="0.2"/>
    </joint>

    <link name="${prefix}left_wheel">
      <collision>
        <origin xyz="0 0 0" rpy="${PI/2} 0 0"/>
        <geometry>
          <cylinder length="${wheel_len}" radius="${wheel_radius}"/>
        </geometry>
      </collision>
      <visual>
        <origin xyz="0 0 0" rpy="${PI/2} 0 0"/>
        <geometry>
          <cylinder length="${wheel_len}" radius="${wheel_radius}"/>
        </geometry>
        <material name="black"/>
      </visual>
      <inertial>
        <origin xyz="0 0 0" rpy="${PI/2} 0 0"/>
        <mass value="${wheel_mass}"/>
        <inertia
          ixx="${wheel_mass / 12.0 * (3*wheel_radius + wheel_len*wheel_len)}" ixy="0.0" ixz="0.0"
          iyy="${wheel_mass / 12.0 * wheel_radius*wheel_radius}" iyz="0.0"
          izz="${wheel_mass / 12.0 * wheel_radius*wheel_radius}"/>
      </inertial>
    </link>

    <joint name="${prefix}right_wheel_joint" type="continuous">
      <parent link="${prefix}base_link"/>
      <child link="${prefix}right_wheel"/>
      <origin xyz="${wheel_distance_from_center} -${base_width/2} ${z_offset}" rpy="0 0 0"/>
      <axis xyz="0 1 0"/>
      <dynamics damping="0.2"/>
    </joint>

    <link name="${prefix}right_wheel">
      <collision>
        <origin xyz="0 0 0" rpy="${PI/2} 0 0"/>
        <geometry>
          <cylinder length="${wheel_len}" radius="${wheel_radius}"/>
        </geometry>
      </collision>
      <visual>
        <origin xyz="0 0 0" rpy="${PI/2} 0 0"/>
        <geometry>
          <cylinder length="${wheel_len}" radius="${wheel_radius}"/>
        </geometry>
        <material name="black"/>
      </visual>
      <inertial>
        <origin xyz="0 0 0" rpy="${PI/2} 0 0"/>
        <mass value="${wheel_mass}"/>
        <inertia
          ixx="${wheel_mass / 12.0 * (3*wheel_radius + wheel_len*wheel_len)}" ixy="0.0" ixz="0.0"
          iyy="${wheel_mass / 12.0 * wheel_radius*wheel_radius}" iyz="0.0"
          izz="${wheel_mass / 12.0 * wheel_radius*wheel_radius}"/>
      </inertial>
    </link>

    <joint name="${prefix}caster_rear_wheel_joint" type="fixed">
      <parent link="${prefix}base_link"/>
      <child link="${prefix}caster_rear_wheel"/>
      <origin xyz="${-base_width/2 + caster_wheel_radius} 0 ${z_offset}" rpy="0 0 0"/>
    </joint>

    <link name="${prefix}caster_rear_wheel">
      <collision>
        <origin xyz="0 0 0" rpy="0 0 0"/>
        <geometry>
          <sphere radius="${caster_wheel_radius}"/>
        </geometry>
      </collision>
      <visual>
        <origin xyz="0 0 0" rpy="0 0 0"/>
        <geometry>
          <sphere radius="${caster_wheel_radius}"/>
        </geometry>
        <material name="white"/>
      </visual>
      <inertial>
        <origin xyz="0 0 0" rpy="0 0 0"/>
        <mass value="${caster_wheel_mass}"/>
        <inertia
          ixx="${caster_wheel_mass * 0.4 * (caster_wheel_radius * caster_wheel_radius)}" ixy="0.0" ixz="0.0"
          iyy="${caster_wheel_mass * 0.4 * (caster_wheel_radius * caster_wheel_radius)}" iyz="0.0"
          izz="${caster_wheel_mass * 0.4 * (caster_wheel_radius * caster_wheel_radius)}"/>
      </inertial>
    </link>

    <joint name="${prefix}gripper_pitch_joint" type="revolute">
      <parent link="${prefix}base_link"/>
      <child link="${prefix}gripper_pitch_link"/>
      <origin xyz="0.15 0 0" rpy="0 0 0"/> 
      <axis xyz="0 1 0"/>
      <limit lower="-1.57" upper="1.57" effort="10" velocity="1.0"/>
    </joint>
    <link name="${prefix}gripper_pitch_link">
      <visual>
        <geometry>
          <box size="0.05 0.05 0.03"/>
        </geometry>
      </visual>
    </link>

    <joint name="${prefix}gripper_claw_joint" type="revolute">
      <parent link="${prefix}gripper_pitch_link"/>
      <child link="${prefix}gripper_claw_link"/>
      <origin xyz="0.05 0 0" rpy="0 0 0"/> 
      <axis xyz="0 1 0"/>
      <limit lower="0" upper="0.5" effort="10" velocity="1.0"/>
    </joint>
    <link name="${prefix}gripper_claw_link">
      <visual>
        <geometry>
            <cylinder radius="0.005" length="0.02"/>
        </geometry>
      </visual>
    </link>

    <joint name="${prefix}head_yaw_joint" type="revolute">
      <parent link="${prefix}base_link"/>
      <child link="${prefix}head_yaw_link"/>
      <origin xyz="0 0 0.205" rpy="0 0 0"/> 
      <axis xyz="0 0 1"/>
      <limit lower="-3.14" upper="3.14" effort="10" velocity="1.0"/>
    </joint>
    <link name="${prefix}head_yaw_link">
      <visual>
        <geometry>
          <box size="0.075 0.085 0.037"/>
        </geometry>
      </visual>
    </link>

    <joint name="${prefix}head_pitch_joint" type="revolute">
      <parent link="${prefix}head_yaw_link"/>
      <child link="${prefix}head_pitch_link"/>
      <origin xyz="0.075 0 0" rpy="0 0 0"/> 
      <axis xyz="0 1 0"/>
      <limit lower="-1.57" upper="1.57" effort="10" velocity="1.0"/>
    </joint>
    <link name="${prefix}head_pitch_link">
      <visual>
        <geometry>
          <box size="0.006 0.117 0.038"/>
        </geometry>
      </visual>
    </link>

  </xacro:macro>
</robot>